2023-04-06 09:48:12,333 (69715/MainThread) pgcli.main INFO - No default pager found in environment. Using os default pager
2023-04-06 09:48:12,333 (69715/MainThread) pgcli.main WARNING - import keyring failed: ModuleNotFoundError("No module named 'keyring'").
2023-08-28 16:50:03,734 (58986/MainThread) pgcli.main INFO - No default pager found in environment. Using os default pager
2023-08-28 16:50:03,737 (58986/MainThread) pgcli.main WARNING - import keyring failed: ModuleNotFoundError("No module named 'keyring'").
2023-08-28 16:50:03,776 (58986/MainThread) pgcli.main ERROR - traceback: 'Traceback (most recent call last):\n  File "/usr/local/Cellar/pgcli/3.5.0_1/libexec/lib/python3.11/site-packages/pgcli/main.py", line 640, in connect\n    raise e\n  File "/usr/local/Cellar/pgcli/3.5.0_1/libexec/lib/python3.11/site-packages/pgcli/main.py", line 627, in connect\n    pgexecute = PGExecute(database, user, passwd, host, port, dsn, **kwargs)\n                ^^^^^^^^^^^^^^^^^^^^^^^^^^^^^^^^^^^^^^^^^^^^^^^^^^^^^^^^^^^^\n  File "/usr/local/Cellar/pgcli/3.5.0_1/libexec/lib/python3.11/site-packages/pgcli/pgexecute.py", line 161, in __init__\n    self.connect(database, user, password, host, port, dsn, **kwargs)\n  File "/usr/local/Cellar/pgcli/3.5.0_1/libexec/lib/python3.11/site-packages/pgcli/pgexecute.py", line 207, in connect\n    conn = psycopg.connect(conn_info)\n           ^^^^^^^^^^^^^^^^^^^^^^^^^^\n  File "/usr/local/Cellar/pgcli/3.5.0_1/libexec/lib/python3.11/site-packages/psycopg/connection.py", line 727, in connect\n    raise ex.with_traceback(None)\npsycopg.OperationalError: connection is bad: No such file or directory\n\tIs the server running locally and accepting connections on that socket?\n'
2023-08-28 17:47:31,640 (71362/MainThread) pgcli.main INFO - No default pager found in environment. Using os default pager
2023-08-28 17:47:31,641 (71362/MainThread) pgcli.main WARNING - import keyring failed: ModuleNotFoundError("No module named 'keyring'").
2023-08-28 17:47:31,650 (71362/MainThread) pgcli.main ERROR - traceback: 'Traceback (most recent call last):\n  File "/usr/local/Cellar/pgcli/3.5.0_1/libexec/lib/python3.11/site-packages/pgcli/main.py", line 640, in connect\n    raise e\n  File "/usr/local/Cellar/pgcli/3.5.0_1/libexec/lib/python3.11/site-packages/pgcli/main.py", line 627, in connect\n    pgexecute = PGExecute(database, user, passwd, host, port, dsn, **kwargs)\n                ^^^^^^^^^^^^^^^^^^^^^^^^^^^^^^^^^^^^^^^^^^^^^^^^^^^^^^^^^^^^\n  File "/usr/local/Cellar/pgcli/3.5.0_1/libexec/lib/python3.11/site-packages/pgcli/pgexecute.py", line 161, in __init__\n    self.connect(database, user, password, host, port, dsn, **kwargs)\n  File "/usr/local/Cellar/pgcli/3.5.0_1/libexec/lib/python3.11/site-packages/pgcli/pgexecute.py", line 207, in connect\n    conn = psycopg.connect(conn_info)\n           ^^^^^^^^^^^^^^^^^^^^^^^^^^\n  File "/usr/local/Cellar/pgcli/3.5.0_1/libexec/lib/python3.11/site-packages/psycopg/connection.py", line 727, in connect\n    raise ex.with_traceback(None)\npsycopg.OperationalError: connection failed: FATAL:  role "root" does not exist\n'
2023-08-28 17:47:39,415 (71394/MainThread) pgcli.main INFO - No default pager found in environment. Using os default pager
2023-08-28 17:47:39,415 (71394/MainThread) pgcli.main WARNING - import keyring failed: ModuleNotFoundError("No module named 'keyring'").
2023-08-28 17:47:39,422 (71394/MainThread) pgcli.main ERROR - traceback: 'Traceback (most recent call last):\n  File "/usr/local/Cellar/pgcli/3.5.0_1/libexec/lib/python3.11/site-packages/pgcli/main.py", line 640, in connect\n    raise e\n  File "/usr/local/Cellar/pgcli/3.5.0_1/libexec/lib/python3.11/site-packages/pgcli/main.py", line 627, in connect\n    pgexecute = PGExecute(database, user, passwd, host, port, dsn, **kwargs)\n                ^^^^^^^^^^^^^^^^^^^^^^^^^^^^^^^^^^^^^^^^^^^^^^^^^^^^^^^^^^^^\n  File "/usr/local/Cellar/pgcli/3.5.0_1/libexec/lib/python3.11/site-packages/pgcli/pgexecute.py", line 161, in __init__\n    self.connect(database, user, password, host, port, dsn, **kwargs)\n  File "/usr/local/Cellar/pgcli/3.5.0_1/libexec/lib/python3.11/site-packages/pgcli/pgexecute.py", line 207, in connect\n    conn = psycopg.connect(conn_info)\n           ^^^^^^^^^^^^^^^^^^^^^^^^^^\n  File "/usr/local/Cellar/pgcli/3.5.0_1/libexec/lib/python3.11/site-packages/psycopg/connection.py", line 727, in connect\n    raise ex.with_traceback(None)\npsycopg.OperationalError: connection failed: FATAL:  database "ivanovyordan" does not exist\n'
